<?xml version="1.0" ?>
<!-- =================================================================================== -->
<!-- |    This document was autogenerated by xacro from static_delta.xacro             | -->
<!-- |    EDITING THIS FILE BY HAND IS NOT RECOMMENDED                                 | -->
<!-- =================================================================================== -->
<robot name="arc_delta_onTable" xmlns:xacro="http://ros.org/wiki/xacro">
  <!-- all links -->
  <!-- all links -->
  <!-- upper leg width -->
  <!-- connector mass-->
  <!--
  <gazebo>
    <plugin filename="libcontact.so" name="my_plugin"/>
    <plugin filename="libgazebo_ros_control.so" name="gazebo_ros_control">
      <robotNamespace>/delta</robotNamespace>
    </plugin>
    <self_collide>true</self_collide>
    <enable_wind>false</enable_wind>
  </gazebo>
-->
  <!-- Used for fixing robot to Gazebo 'base_link'
  <link name="world"/>-->
  <link name="world"/>
  <joint name="base" type="fixed">
    <parent link="world"/>
    <child link="link_0"/>
    <axis xyz="0 0 0"/>
    <origin rpy="0 0 0" xyz="0 0 1.359"/>
  </joint>
  <gazebo reference="link_w_JOINT_w2">
    <physics>
      <ode>
        <provide_feedback>true</provide_feedback>
      </ode>
    </physics>
  </gazebo>
  <link name="link_0">
    <inertial>
      <origin rpy="0 0 0" xyz="-0.0 -0.0 -0.0"/>
      <mass value="0.48"/>
      <inertia ixx="0.003604" ixy="0.0" ixz="0.0" iyy="0.003604" iyz="0.0" izz="0.0072"/>
    </inertial>
    <visual>
      <origin rpy="0 0 0" xyz="-0.147 -0.085 -0.01"/>
      <geometry>
        <mesh filename="package://mara_description/meshes/fixed_base2.dae" scale="0.001 0.001 0.001"/>
      </geometry>
    </visual>
    <visual>
      <origin rpy="0 0 0" xyz="-0.0 0 0.06"/>
      <geometry>
        <box size="0.05 0.05 0.12  "/>
      </geometry>
    </visual>
    <collision>
      <origin rpy="0 0 0" xyz="-0.147 -0.085 -0.01"/>
      <geometry>
        <mesh filename="package://mara_description/meshes/fixed_base2.dae" scale="0.001 0.001 0.001"/>
      </geometry>
    </collision>
  </link>
  <gazebo reference="link_0">
    <visual>
      <material>
        <script>
          <uri>file://media/materials/scripts/gazebo.material</uri>
          <name>Gazebo/Red</name>
        </script>
      </material>
    </visual>
  </gazebo>
  <gazebo reference="uleg_1">
    <visual>
      <material>
        <script>
          <uri>file://media/materials/scripts/gazebo.material</uri>
          <name>Gazebo/Red</name>
        </script>
      </material>
    </visual>
  </gazebo>
  <gazebo reference="uleg_2">
    <visual>
      <material>
        <script>
          <uri>file://media/materials/scripts/gazebo.material</uri>
          <name>Gazebo/Red</name>
        </script>
      </material>
    </visual>
  </gazebo>
  <gazebo reference="uleg_3">
    <visual>
      <material>
        <script>
          <uri>file://media/materials/scripts/gazebo.material</uri>
          <name>Gazebo/Red</name>
        </script>
      </material>
    </visual>
  </gazebo>
  <gazebo reference="low_base">
    <visual>
      <material>
        <script>
          <uri>file://media/materials/scripts/gazebo.material</uri>
          <name>Gazebo/Red</name>
        </script>
      </material>
    </visual>
  </gazebo>
  <joint name="motor1" type="revolute">
    <origin rpy="0 0 0" xyz="0 -0.08585 0"/>
    <parent link="link_0"/>
    <child link="uleg_1"/>
    <limit effort="20" lower="-1.1" upper="1.1" velocity="1.57"/>
    <axis xyz="1 0 0"/>
  </joint>
  <joint name="motor2" type="revolute">
    <origin rpy="0 0 4.18879020479" xyz="-0.075 0.047925 0"/>
    <parent link="link_0"/>
    <child link="uleg_2"/>
    <limit effort="20" lower="-1.1" upper="1.1" velocity="1.57"/>
    <axis xyz="1 0 0"/>
  </joint>
  <joint name="motor3" type="revolute">
    <origin rpy="0 0 2.09439510239" xyz="0.075 0.042925 0"/>
    <parent link="link_0"/>
    <child link="uleg_3"/>
    <limit effort="20" lower="-1.1" upper="1.1" velocity="1.57"/>
    <axis xyz="1 0 0"/>
  </joint>
  <link name="uleg_1">
    <inertial>
      <origin rpy="1.57079632679 0 0" xyz="0 -0.071  0 "/>
      <mass value="0.0466"/>
      <inertia ixx="0.000165041666667" ixy="0.0" ixz="0.0" iyy="0.000165041666667" iyz="0.0" izz="1.94166666667e-05"/>
    </inertial>
    <visual>
      <origin rpy="1.57079632679 3.14159265359 1.57079632679" xyz="0 0.029 0.028 "/>
      <geometry>
        <mesh filename="package://mara_description/meshes/upper_leg.STL" scale="0.001 0.001 0.001"/>
      </geometry>
    </visual>
    <collision>
      <origin rpy="1.57079632679 3.14159265359 1.57079632679" xyz="0 0.029 0.025 "/>
      <geometry>
        <mesh filename="package://mara_description/meshes/upper_leg.STL" scale="0.001 0.001 0.001"/>
      </geometry>
    </collision>
  </link>
  <link name="uleg_2">
    <inertial>
      <origin rpy="1.57079632679 0 0" xyz="0 -0.071  0 "/>
      <mass value="0.0466"/>
      <inertia ixx="0.000165041666667" ixy="0.0" ixz="0.0" iyy="0.000165041666667" iyz="0.0" izz="1.94166666667e-05"/>
    </inertial>
    <visual>
      <origin rpy="1.57079632679 3.14159265359 1.57079632679" xyz="0 0.029 0.028 "/>
      <geometry>
        <mesh filename="package://mara_description/meshes/upper_leg.STL" scale="0.001 0.001 0.001"/>
      </geometry>
    </visual>
    <collision>
      <origin rpy="1.57079632679 3.14159265359 1.57079632679" xyz="0 0.029 0.025 "/>
      <geometry>
        <mesh filename="package://mara_description/meshes/upper_leg.STL" scale="0.001 0.001 0.001"/>
      </geometry>
    </collision>
  </link>
  <link name="uleg_3">
    <inertial>
      <origin rpy="1.57079632679 0 0" xyz="0 -0.071  0 "/>
      <mass value="0.0466"/>
      <inertia ixx="0.000165041666667" ixy="0.0" ixz="0.0" iyy="0.000165041666667" iyz="0.0" izz="1.94166666667e-05"/>
    </inertial>
    <visual>
      <origin rpy="1.57079632679 3.14159265359 1.57079632679" xyz="0 0.029 0.028 "/>
      <geometry>
        <mesh filename="package://mara_description/meshes/upper_leg.STL" scale="0.001 0.001 0.001"/>
      </geometry>
    </visual>
    <collision>
      <origin rpy="1.57079632679 3.14159265359 1.57079632679" xyz="0 0.029 0.025 "/>
      <geometry>
        <mesh filename="package://mara_description/meshes/upper_leg.STL" scale="0.001 0.001 0.001"/>
      </geometry>
    </collision>
  </link>
  <joint name="uleg1_con" type="continuous">
    <origin rpy="0.534996326795 0 0" xyz="0 -0.2 0"/>
    <parent link="uleg_1"/>
    <child link="con1"/>
    <axis xyz="1 0 0"/>
  </joint>
  <link name="con1">
    <inertial>
      <origin rpy="0 1.57079632679 0" xyz="0.005 0 0 "/>
      <mass value="0.0173"/>
      <inertia ixx="3.60993333333e-06" ixy="0.0" ixz="0.0" iyy="3.60993333333e-06" iyz="0.0" izz="1.15333333333e-08"/>
    </inertial>
    <visual>
      <origin rpy="0 1.57079632679 0" xyz="0.005 0 0 "/>
      <geometry>
        <cylinder length="0.05" radius="0.002"/>
      </geometry>
    </visual>
    <collision>
      <origin rpy="0 1.57079632679 0 " xyz="0.005 0 0 "/>
      <geometry>
        <cylinder length="0.05" radius="0.002"/>
      </geometry>
    </collision>
  </link>
  <joint name="con_lleg_1" type="continuous">
    <origin rpy="0 0 0" xyz="-0.02 0 0"/>
    <parent link="con1"/>
    <child link="lleg_1"/>
    <axis xyz="0 1 0"/>
  </joint>
  <link name="lleg_1">
    <inertial>
      <origin rpy="0 0 0" xyz="0 0 -0.255 "/>
      <mass value="0.04"/>
      <inertia ixx="0.000867013333333" ixy="0.0" ixz="0.0" iyy="0.000867013333333" iyz="0.0" izz="2.66666666667e-08"/>
    </inertial>
    <visual>
      <origin rpy="0 0 0" xyz=" 0 0 -0.255 "/>
      <geometry>
        <cylinder length="0.51" radius="0.002"/>
      </geometry>
    </visual>
    <collision>
      <origin rpy="0 0 0 " xyz="0 0 -0.255 "/>
      <geometry>
        <cylinder length="0.51" radius="0.002"/>
      </geometry>
    </collision>
  </link>
  <joint name="con2_lleg_1" type="continuous">
    <origin rpy="0 0 0" xyz="0.03 0 0"/>
    <parent link="con1"/>
    <child link="lleg_12"/>
    <mimic joint="con_lleg_1"/>
    <axis xyz="0 1 0"/>
  </joint>
  <link name="lleg_12">
    <inertial>
      <origin rpy="0 0 0" xyz="0 0 -0.255 "/>
      <mass value="0.04"/>
      <inertia ixx="0.000867013333333" ixy="0.0" ixz="0.0" iyy="0.000867013333333" iyz="0.0" izz="2.66666666667e-08"/>
    </inertial>
    <visual>
      <origin rpy="0 0 0" xyz=" 0 0 -0.255 "/>
      <geometry>
        <cylinder length="0.51" radius="0.002"/>
      </geometry>
    </visual>
    <collision>
      <origin rpy="0 0 0 " xyz="0 0 -0.255 "/>
      <geometry>
        <cylinder length="0.51" radius="0.002"/>
      </geometry>
    </collision>
  </link>
  <joint name="uleg2_con" type="continuous">
    <origin rpy="0.534996326795 0 0" xyz="0 -0.2 0"/>
    <parent link="uleg_2"/>
    <child link="con2"/>
    <axis xyz="1 0 0"/>
  </joint>
  <link name="con2">
    <inertial>
      <origin rpy="0 1.57079632679 0" xyz="0.005 0 0 "/>
      <mass value="0.0173"/>
      <inertia ixx="3.60993333333e-06" ixy="0.0" ixz="0.0" iyy="3.60993333333e-06" iyz="0.0" izz="1.15333333333e-08"/>
    </inertial>
    <visual>
      <origin rpy="0 1.57079632679 0" xyz="0.005 0 0 "/>
      <geometry>
        <cylinder length="0.05" radius="0.002"/>
      </geometry>
    </visual>
    <collision>
      <origin rpy="0 1.57079632679 0 " xyz="0.005 0 0 "/>
      <geometry>
        <cylinder length="0.05" radius="0.002"/>
      </geometry>
    </collision>
  </link>
  <joint name="con_lleg_2" type="continuous">
    <origin rpy="0 0 0" xyz="-0.02 0 0"/>
    <parent link="con2"/>
    <child link="lleg_2"/>
    <axis xyz="0 1 0"/>
  </joint>
  <link name="lleg_2">
    <inertial>
      <origin rpy="0 0 0" xyz="0 0 -0.255 "/>
      <mass value="0.04"/>
      <inertia ixx="0.000867013333333" ixy="0.0" ixz="0.0" iyy="0.000867013333333" iyz="0.0" izz="2.66666666667e-08"/>
    </inertial>
    <visual>
      <origin rpy="0 0 0" xyz=" 0 0 -0.255 "/>
      <geometry>
        <cylinder length="0.51" radius="0.002"/>
      </geometry>
    </visual>
    <collision>
      <origin rpy="0 0 0 " xyz="0 0 -0.255 "/>
      <geometry>
        <cylinder length="0.51" radius="0.002"/>
      </geometry>
    </collision>
  </link>
  <joint name="con2_lleg_2" type="continuous">
    <origin rpy="0 0 0" xyz="0.03 0 0"/>
    <parent link="con2"/>
    <child link="lleg_22"/>
    <axis xyz="0 1 0"/>
  </joint>
  <link name="lleg_22">
    <inertial>
      <origin rpy="0 0 0" xyz="0 0 -0.255 "/>
      <mass value="0.04"/>
      <inertia ixx="0.000867013333333" ixy="0.0" ixz="0.0" iyy="0.000867013333333" iyz="0.0" izz="2.66666666667e-08"/>
    </inertial>
    <visual>
      <origin rpy="0 0 0" xyz=" 0 0 -0.255 "/>
      <geometry>
        <cylinder length="0.51" radius="0.002"/>
      </geometry>
    </visual>
    <collision>
      <origin rpy="0 0 0 " xyz="0 0 -0.255 "/>
      <geometry>
        <cylinder length="0.51" radius="0.002"/>
      </geometry>
    </collision>
  </link>
  <joint name="uleg3_con" type="continuous">
    <origin rpy="0.534996326795 0 0" xyz="0 -0.2 0"/>
    <parent link="uleg_3"/>
    <child link="con3"/>
    <axis xyz="1 0 0"/>
  </joint>
  <link name="con3">
    <inertial>
      <origin rpy="0 1.57079632679 0" xyz="0.005 0 0 "/>
      <mass value="0.0173"/>
      <inertia ixx="3.60993333333e-06" ixy="0.0" ixz="0.0" iyy="3.60993333333e-06" iyz="0.0" izz="1.15333333333e-08"/>
    </inertial>
    <visual>
      <origin rpy="0 1.57079632679 0" xyz="0.005 0 0 "/>
      <geometry>
        <cylinder length="0.05" radius="0.002"/>
      </geometry>
    </visual>
    <collision>
      <origin rpy="0 1.57079632679 0 " xyz="0.005 0 0 "/>
      <geometry>
        <cylinder length="0.05" radius="0.002"/>
      </geometry>
    </collision>
  </link>
  <joint name="con_lleg_3" type="continuous">
    <origin rpy="0 0 0" xyz="-0.02 0 0"/>
    <parent link="con3"/>
    <child link="lleg_3"/>
    <axis xyz="0 1 0"/>
  </joint>
  <link name="lleg_3">
    <inertial>
      <origin rpy="0 0 0" xyz="0 0 -0.255 "/>
      <mass value="0.04"/>
      <inertia ixx="0.000867013333333" ixy="0.0" ixz="0.0" iyy="0.000867013333333" iyz="0.0" izz="2.66666666667e-08"/>
    </inertial>
    <visual>
      <origin rpy="0 0 0" xyz=" 0 0 -0.255 "/>
      <geometry>
        <cylinder length="0.51" radius="0.002"/>
      </geometry>
    </visual>
    <collision>
      <origin rpy="0 0 0 " xyz="0 0 -0.255 "/>
      <geometry>
        <cylinder length="0.51" radius="0.002"/>
      </geometry>
    </collision>
  </link>
  <joint name="con2_lleg_3" type="continuous">
    <origin rpy="0 0 0" xyz="0.03 0 0"/>
    <parent link="con3"/>
    <child link="lleg_32"/>
    <axis xyz="0 1 0"/>
  </joint>
  <link name="lleg_32">
    <inertial>
      <origin rpy="0 0 0" xyz="0 0 -0.255 "/>
      <mass value="0.04"/>
      <inertia ixx="0.000867013333333" ixy="0.0" ixz="0.0" iyy="0.000867013333333" iyz="0.0" izz="2.66666666667e-08"/>
    </inertial>
    <visual>
      <origin rpy="0 0 0" xyz=" 0 0 -0.255 "/>
      <geometry>
        <cylinder length="0.51" radius="0.002"/>
      </geometry>
    </visual>
    <collision>
      <origin rpy="0 0 0 " xyz="0 0 -0.255 "/>
      <geometry>
        <cylinder length="0.51" radius="0.002"/>
      </geometry>
    </collision>
  </link>
  <joint name="con33_lleg_3" type="continuous">
    <origin rpy="0 0 0" xyz="0 0 -0.51"/>
    <parent link="lleg_32"/>
    <child link="con33"/>
    <axis xyz="0 1 0"/>
  </joint>
  <link name="con33">
    <inertial>
      <origin rpy="0 1.57079632679 0" xyz="-0.025  0 0 "/>
      <mass value="0.0173"/>
      <inertia ixx="3.60993333333e-06" ixy="0.0" ixz="0.0" iyy="3.60993333333e-06" iyz="0.0" izz="1.15333333333e-08"/>
    </inertial>
    <visual>
      <origin rpy="0 1.57079632679 0" xyz="-0.025 0 0  "/>
      <geometry>
        <cylinder length="0.05" radius="0.002"/>
      </geometry>
    </visual>
    <collision>
      <origin rpy="0 1.57079632679 0 " xyz="-0.025 0  0 "/>
      <geometry>
        <cylinder length="0.05" radius="0.002"/>
      </geometry>
    </collision>
  </link>
  <joint name="con23_lleg_2" type="continuous">
    <origin rpy="0 0 0" xyz="0 0 -0.51"/>
    <parent link="lleg_22"/>
    <child link="con23"/>
    <axis xyz="0 1 0"/>
  </joint>
  <link name="con23">
    <inertial>
      <origin rpy="0 1.57079632679 0" xyz="-0.025  0 0 "/>
      <mass value="0.0173"/>
      <inertia ixx="3.60993333333e-06" ixy="0.0" ixz="0.0" iyy="3.60993333333e-06" iyz="0.0" izz="1.15333333333e-08"/>
    </inertial>
    <visual>
      <origin rpy="0 1.57079632679 0" xyz="-0.025 0 0  "/>
      <geometry>
        <cylinder length="0.05" radius="0.002"/>
      </geometry>
    </visual>
    <collision>
      <origin rpy="0 1.57079632679 0 " xyz="-0.025 0  0 "/>
      <geometry>
        <cylinder length="0.05" radius="0.002"/>
      </geometry>
    </collision>
  </link>
  <joint name="con13_lleg_1" type="continuous">
    <origin rpy="0 0 0" xyz="0 0 -0.51"/>
    <parent link="lleg_12"/>
    <child link="con13"/>
    <axis xyz="0 1 0"/>
  </joint>
  <link name="con13">
    <inertial>
      <origin rpy="0 1.57079632679 0" xyz="-0.025  0 0 "/>
      <mass value="0.0173"/>
      <inertia ixx="3.60993333333e-06" ixy="0.0" ixz="0.0" iyy="3.60993333333e-06" iyz="0.0" izz="1.15333333333e-08"/>
    </inertial>
    <visual>
      <origin rpy="0 1.57079632679 0" xyz="-0.025 0 0  "/>
      <geometry>
        <cylinder length="0.05" radius="0.002"/>
      </geometry>
    </visual>
    <collision>
      <origin rpy="0 1.57079632679 0 " xyz="-0.025 0  0 "/>
      <geometry>
        <cylinder length="0.05" radius="0.002"/>
      </geometry>
    </collision>
  </link>
  <joint name="lleg1_base" type="continuous">
    <origin rpy="-0.5 0 0" xyz=" 0 0 0"/>
    <parent link="con13"/>
    <child link="low_base"/>
    <axis xyz="1 0 0"/>
  </joint>
  <link name="low_base">
    <inertial>
      <origin rpy="0 -0 0" xyz="-0.03 0.03 0"/>
      <mass value="0.014"/> <!-- 0.03-->
      <inertia ixx="4.5e-06" ixy="0.0" ixz="0.0" iyy="4.5e-06" iyz="0.0" izz="4.5e-06"/>
    </inertial>
    <visual>

      <origin rpy="0 -0 0" xyz="-0.07 -0.015 -0.012"/>
      <geometry>
        <mesh filename="package://mara_description/meshes/Platform.STL" scale="0.001 0.001 0.001"/>
      </geometry>
    </visual>
  </link>
  <gazebo>
    <joint name="lleg2_base" type="revolute">
      <child>con23</child>
      <parent>low_base</parent>
      <pose> 0 0 0 0 0 0 </pose>
      <axis>
        <xyz>1 0 0</xyz>
        <limit>
          <lower>-100</lower>
          <upper>100</upper>
        </limit>
        <dynamics>
          <spring_reference>0</spring_reference>
          <spring_stiffness>0</spring_stiffness>
          <damping>0.000000</damping>
          <friction>0.00030000</friction>
        </dynamics>
        <use_parent_model_frame>0</use_parent_model_frame>
      </axis>
    </joint>
    <joint name="lleg3_base" type="revolute">
      <child>con33</child>
      <parent>low_base</parent>
      <pose> 0 0 0 0 0 0 </pose>
      <axis>
        <xyz>1 0 0</xyz>
        <limit>
          <lower>-100</lower>
          <upper>100</upper>
        </limit>
        <dynamics>
          <spring_reference>0</spring_reference>
          <spring_stiffness>0</spring_stiffness>
          <damping>0.000000</damping>
          <friction>0.00030000</friction>
        </dynamics>
        <use_parent_model_frame>0</use_parent_model_frame>
      </axis>
    </joint>
    <joint name="con13_lleg_12" type="revolute">
      <child>con13</child>
      <parent>lleg_1</parent>
      <pose> -0.05 0 0 0 0 0 </pose>
      <axis>
        <xyz>0 1 0</xyz>
        <limit>
          <lower>-100</lower>
          <upper>100</upper>
        </limit>
        <dynamics>
          <spring_reference>0</spring_reference>
          <spring_stiffness>0</spring_stiffness>
          <damping>0.000000</damping>
          <friction>0.00030000</friction>
        </dynamics>
        <use_parent_model_frame>0</use_parent_model_frame>
      </axis>
    </joint>
    <joint name="con23_lleg_22" type="revolute">
      <child>con23</child>
      <parent>lleg_2</parent>
      <pose> -0.05 0 0 0 0 0 </pose>
      <axis>
        <xyz>0 1 0</xyz>
        <limit>
          <lower>-100</lower>
          <upper>100</upper>
        </limit>
        <dynamics>
          <spring_reference>0</spring_reference>
          <spring_stiffness>0</spring_stiffness>
          <damping>0.000000</damping>
          <friction>0.00030000</friction>
        </dynamics>
        <use_parent_model_frame>0</use_parent_model_frame>
      </axis>
    </joint>
    <joint name="con33_lleg_32" type="revolute">
      <child>con33</child>
      <parent>lleg_3</parent>
      <pose> -0.05 0 0 0 0 0 </pose>
      <axis>
        <xyz>0 1 0</xyz>
        <limit>
          <lower>-100</lower>
          <upper>100</upper>
        </limit>
        <dynamics>
          <spring_reference>0</spring_reference>
          <spring_stiffness>0</spring_stiffness>
          <damping>0.000000</damping>
          <friction>0.00030000</friction>
        </dynamics>
        <use_parent_model_frame>0</use_parent_model_frame>
      </axis>
    </joint>
    <model name="sharp_box1">
      <static>false</static>
      <pose>1.38081283544e-05 0.209778773089 0.7 0 0 0</pose>
      <link name="link">
        <inertial>
          <mass>0.010</mass>
          <inertia ixx="0.0" ixy="0.0" ixz="0.0" iyy="0.0" iyz="0.0" izz="0.0"/>
        </inertial>
        <collision name="collision">
          <geometry>
            <box>
              <size>0.025 0.01 0.06</size>
            </box>
          </geometry>
          <surface>
            <friction>
              <ode>
                <mu>1.01000</mu>
                <mu2>1.01000</mu2>
                <fdir1>0.000000 0.000000 0.000000</fdir1>
                <slip1>0.000000</slip1>
                <slip2>0.000000</slip2>
              </ode>
            </friction>
            <contact>
              <ode>
                <soft_cfm>0.000000</soft_cfm>
                <soft_erp>0.200000</soft_erp>
                <kp>100000.000000</kp>
                <kd>1.000000</kd>
                <max_vel>100.000000</max_vel>
                <min_depth>0.001000</min_depth>
              </ode>
            </contact>
          </surface>
        </collision>
        <visual name="visual">
          <cast_shadows>true</cast_shadows>
          <geometry>
            <box>
              <size>0.025 0.01 0.06</size>
            </box>
          </geometry>
          <material>
            <script>
              <uri>file://media/materials/scripts/gazebo.material</uri>
              <name>Gazebo/Grey</name>
            </script>
          </material>
        </visual>
      </link>
    </model>

    <model name="sharp_box2">
      <static>false</static>
      <pose>-0.0999984355292 0.099996952657 0.7 0 0 0</pose>
      <link name="link">
        <inertial>
          <mass>0.001</mass>
          <inertia ixx="0.0" ixy="0.0" ixz="0.0" iyy="0.0" iyz="0.0" izz="0.0"/>
        </inertial>
        <collision name="collision">
          <geometry>
            <box>
              <size>0.025 0.01 0.06</size>
            </box>
          </geometry>
          <surface>
            <friction>
              <ode>
                <mu>100000</mu>
                <mu2>100000</mu2>
              </ode>
            </friction>
          </surface>
        </collision>
        <visual name="visual">
          <cast_shadows>true</cast_shadows>
          <geometry>
            <box>
              <size>0.025 0.01 0.06</size>
            </box>
          </geometry>
          <material>
            <script>
              <uri>file://media/materials/scripts/gazebo.material</uri>
              <name>Gazebo/Grey</name>
            </script>
          </material>
        </visual>
      </link>
    </model>

    <model name="sharp_box3">
      <static>false</static>
      <pose>0.0999976168609 0.150001818126 0.7 0 0 0</pose>
      <link name="link">
        <inertial>
          <mass>0.001</mass>
          <inertia ixx="0.0" ixy="0.0" ixz="0.0" iyy="0.0" iyz="0.0" izz="0.0"/>
        </inertial>
        <collision name="collision">
          <geometry>
            <box>
              <size>0.025 0.01 0.06</size>
            </box>
          </geometry>
          <surface>
            <friction>
              <ode>
                <mu>100000</mu>
                <mu2>100000</mu2>
              </ode>
            </friction>
          </surface>
        </collision>
        <visual name="visual">
          <cast_shadows>true</cast_shadows>
          <geometry>
            <box>
              <size>0.025 0.01 0.06</size>
            </box>
          </geometry>
          <material>
            <script>
              <uri>file://media/materials/scripts/gazebo.material</uri>
              <name>Gazebo/Grey</name>
            </script>
          </material>
        </visual>
      </link>
    </model>

    <model name="sharp_box4">
      <static>false</static>
      <pose>0.0899073798131 9.62382843279e-05 0.7 0 0 0</pose>
      <link name="link">
        <inertial>
          <mass>0.001</mass>
          <inertia ixx="0.0" ixy="0.0" ixz="0.0" iyy="0.0" iyz="0.0" izz="0.0"/>
        </inertial>
        <collision name="collision">
          <geometry>
            <box>
              <size>0.025 0.01 0.06</size>
            </box>
          </geometry>
          <surface>
            <friction>
              <ode>
                <mu>100000</mu>
                <mu2>100000</mu2>
              </ode>
            </friction>
          </surface>
        </collision>
        <visual name="visual">
          <cast_shadows>true</cast_shadows>
          <geometry>
            <box>
              <size>0.025 0.01 0.06</size>
            </box>
          </geometry>
          <material>
            <script>
              <uri>file://media/materials/scripts/gazebo.material</uri>
              <name>Gazebo/Grey</name>
            </script>
          </material>
        </visual>
      </link>
    </model>

    <model name="sharp_box5">
      <static>false</static>
      <pose>-0.00937140177285 0.0580800116273 0.7 0 0 0</pose>
      <link name="link">
        <inertial>
          <mass>0.001</mass>
          <inertia ixx="0.0" ixy="0.0" ixz="0.0" iyy="0.0" iyz="0.0" izz="0.0"/>
        </inertial>
        <collision name="collision">
          <geometry>
            <box>
              <size>0.025 0.01 0.06</size>
            </box>
          </geometry>
          <surface>
            <friction>
              <ode>
                <mu>100000</mu>
                <mu2>100000</mu2>
              </ode>
            </friction>
          </surface>
        </collision>
        <visual name="visual">
          <cast_shadows>true</cast_shadows>
          <geometry>
            <box>
              <size>0.025 0.01 0.06</size>
            </box>
          </geometry>
          <material>
            <script>
              <uri>file://media/materials/scripts/gazebo.material</uri>
              <name>Gazebo/Grey</name>
            </script>
          </material>
        </visual>
      </link>
    </model>
    <include>
      <uri>model://bowl</uri>
      <static>false</static>
      <pose>0.28 -0.07 0.7 0 0 0 </pose>
      <minDepth>0.0005</minDepth>
      <surface>
        <friction>
          <ode>
            <mu>100000</mu>
            <mu2>100000</mu2>
          </ode>
        </friction>
      </surface>
    </include>
  </gazebo>
  <transmission name="uleg_1_trans">
    <type>transmission_interface/SimpleTransmission</type>
    <joint name="motor1">
      <hardwareInterface>hardware_interface/PositionJointInterface</hardwareInterface>
    </joint>
    <actuator name="uleg_1_motor1">
      <mechanicalReduction>1</mechanicalReduction>
    </actuator>
  </transmission>
  <transmission name="uleg_2_trans">
    <type>transmission_interface/SimpleTransmission</type>
    <joint name="motor2">
      <hardwareInterface>hardware_interface/PositionJointInterface</hardwareInterface>
    </joint>
    <actuator name="uleg_2_motor2">
      <mechanicalReduction>1</mechanicalReduction>
    </actuator>
  </transmission>
  <transmission name="uleg_3_trans">
    <type>transmission_interface/SimpleTransmission</type>
    <joint name="motor3">
      <hardwareInterface>hardware_interface/PositionJointInterface</hardwareInterface>
    </joint>
    <actuator name="uleg_3_motor3">
      <mechanicalReduction>1</mechanicalReduction>
    </actuator>
  </transmission>


  <!-- Add end point at lower base of delta robot -->
  <!--
    <link name="ee_link">
      <visual>
        <geometry>
          <sphere radius="0.01"/>
        </geometry>
        <material name="Gazebo/Grey">
          <color rgba="0. 0. 0. 1"/>
        </material>
      </visual>
    </link>
    <gazebo reference="ee_link">
      <material>Gazebo/Blue</material>
      <selfCollide>False</selfCollide>
    </gazebo>
    <joint name="ee_link" type="fixed">
      <origin rpy="0 -1.57 0" xyz="-0.03 0.027 -0.04"/>
      <parent link="low_base"/>
      <child link="ee_link"/>
    </joint>
  -->
  <!-- Add Goal point in environment wrt word -->
  <!--
    <link name="goal_point">
      <visual>
        <geometry>
          <sphere radius="0.01"/>
        </geometry>
        <material name="Gazebo/Grey">
          <color rgba="0. 1. 0. 1"/>
        </material>
      </visual>
    </link>
    <gazebo reference="goal_point">
      <material>Gazebo/Blue</material>
      <selfCollide>False</selfCollide>
    </gazebo>
    <joint name= "link_0__goal_point" type="fixed">
      <origin rpy="0 0 0" xyz="0.2 0.2 -0.5"/>
      <parent link="link_0"/>
      <child link="goal_point"/>
    </joint>
  -->

<!-- TABLE LINK **********************************************-->

    <link name="table">
      <contact>
        <lateral_friction value="1.0"/>
      </contact>
      <inertial>
        <origin rpy="0 0 0" xyz="0 0 0"/>
        <mass value="0.00001"/>
        <inertia ixx="0.001" ixy="0" ixz="0" iyy="0.001" iyz="0" izz="0.001"/>
      </inertial>
      <visual>
        <origin rpy="0 0 0" xyz="0 0 0.6"/>
        <geometry>
          <mesh filename="package://mara_description/urdf/table.obj" scale="1.5 1 0.05"/>
        </geometry>
        <material name="brown">
          <color rgba="0.63 0.16 0.16 1"/>
        </material>
      </visual>
      <collision>
        <origin rpy="0 0 0" xyz="0 0 0.6"/>
        <geometry>
          <box size="1.5 1 0.05"/>
        </geometry>
      </collision>
      <visual>
        <origin rpy="0 0 0" xyz="-0.65 -0.4 0.29"/>
        <geometry>
          <mesh filename="package://mara_description/urdf/table.obj" scale="0.1 0.1 0.58"/>
        </geometry>
        <material name="framemat0"/>
      </visual>
      <visual>
        <origin rpy="0 0 0" xyz="-0.65 0.4 0.29"/>
        <geometry>
          <mesh filename="package://mara_description/urdf/table.obj" scale="0.1 0.1 0.58"/>
        </geometry>
        <material name="framemat0"/>
      </visual>
      <visual>
        <origin rpy="0 0 0" xyz="0.65 -0.4 0.29"/>
        <geometry>
          <mesh filename="package://mara_description/urdf/table.obj" scale="0.1 0.1 0.58"/>
        </geometry>
        <material name="framemat0"/>
      </visual>
      <visual>
        <origin rpy="0 0 0" xyz="0.65 0.4 0.29"/>
        <geometry>
          <mesh filename="package://mara_description/urdf/table.obj" scale="0.1 0.1 0.58"/>
        </geometry>
      </visual>
    </link>
    <gazebo reference="table">
      <material>Gazebo/Brown</material>
      <selfCollide>True</selfCollide>
      <kinematic>True</kinematic>
    </gazebo>
    <joint name="world_to_table_joint" type="fixed">
      <origin rpy="0 0 0" xyz="0 0 0"/>
      <parent link="world"/>
      <child link="table"/>
    </joint>



<!-- GRIPPER ******************************************-->
    <joint name="low_base_to_robotiq_arg2f_base_link" type="fixed">
      <origin rpy="3.14 0 0" xyz="-0.03 0.027 0"/>
      <parent link="low_base"/>
      <child link="robotiq_arg2f_base_link"/>
    </joint>
 <!--
    <link name="robotiq_adapter_link">
      <inertial>
        <origin rpy="0 0 0" xyz="8.625E-08 -4.6583E-06 0.03145"/>
        <mass value="0.22652"/>
        <inertia ixx="0.00020005" ixy="0" ixz="0" iyy="0.00017832" iyz="0" izz="0.00013478"/>
      </inertial>
      <visual>
        <origin rpy="0 0 1.57" xyz="0 0 0"/>
        <geometry>
          <mesh filename="package://mara_description/meshes/hros_robotiq_adapter.dae" scale="0.001 0.001 0.001"/>
        </geometry>
        <material name="Gazebo/Black">
          <color rgba="0.0 0.0 0.0 1"/>
        </material>
      </visual>
      <collision>
        <origin rpy="0 0 1.57" xyz="0 0 0"/>
        <geometry>
          <mesh filename="package://mara_description/meshes/hros_robotiq_adapter.dae" scale="0.001 0.001 0.001"/>
        </geometry>
      </collision>
    </link>

    <gazebo reference="robotiq_adapter_link">
      <material>Gazebo/Black</material>
      <selfCollide>False</selfCollide>
    </gazebo>

    <joint name="base_adapter_to_base_robotiq_joint" type="fixed">
      <origin rpy="0 0 0" xyz=" 0 0 0.03653"/>
      <parent link="robotiq_adapter_link"/>
      <child link="robotiq_arg2f_base_link"/>
    </joint>
-->
    <link name="robotiq_arg2f_base_link">
      <inertial>
        <origin rpy="0 0 0" xyz="8.625E-08 -4.6583E-06 0.03145"/>
	<mass value="0.008"/> <!--0.22652-->
        <inertia ixx="0.00020005" ixy="0" ixz="0" iyy="0.00017832" iyz="0" izz="0.00013478"/>
      </inertial>
      <visual>
        <origin rpy="0 0 1.57" xyz="0 0 0"/>
        <geometry>
          <mesh filename="package://robotiq_140_gripper_description/meshes/GRIPPER_base_axis.dae" scale="0.001 0.001 0.001"/>
        </geometry>
        <material name="Gazebo/Black">
          <color rgba="0.1 0.1 0.1 1"/>
        </material>
      </visual>
      <collision>
        <origin rpy="0 0 1.57" xyz="0 0 0"/>
        <geometry>
          <mesh filename="package://robotiq_140_gripper_description/meshes/GRIPPER_base_axis.dae" scale="0.001 0.001 0.001"/>
        </geometry>
      </collision>
    </link>
    <gazebo reference="robotiq_arg2f_base_link">
      <material>Gazebo/Black</material>
      <selfCollide>False</selfCollide>
    </gazebo>
    <link name="left_outer_knuckle">
      <inertial>
        <origin rpy="0 0 0" xyz="0 0 0"/>
	<mass value="0.002"/> <!--0.00853198276973456"-->
        <inertia ixx="2.89328108496468E-06" ixy="-1.57935047237397E-19" ixz="-1.93980378593255E-19" iyy="1.86719750325683E-06" iyz="-1.21858577871576E-06" izz="1.21905238907251E-06"/>
      </inertial>
      <visual>
        <origin rpy="0 0 0" xyz="0 0 0"/>
        <geometry>
          <mesh filename="package://robotiq_140_gripper_description/meshes/robotiq_140_left_outer_knuckle.dae"/>
        </geometry>
        <material name="">
          <color rgba="0.792156862745098 0.819607843137255 0.933333333333333 1"/>
        </material>
      </visual>
      <collision>
        <origin rpy="0 0 0" xyz="0 0 0"/>
        <geometry>
          <mesh filename="package://robotiq_140_gripper_description/meshes/robotiq_140_left_outer_knuckle.dae"/>
        </geometry>
      </collision>
    </link>
    <gazebo reference="left_outer_knuckle">
      <material>Gazebo/Grey</material>
      <selfCollide>False</selfCollide>
    </gazebo>
    <link name="right_outer_knuckle">
      <inertial>
        <origin rpy="0 0 0" xyz="0 0 0"/>
	<mass value="0.002"/> <!--0.00853198276973456"-->
        <inertia ixx="2.89328108496468E-06" ixy="-1.57935047237397E-19" ixz="-1.93980378593255E-19" iyy="1.86719750325683E-06" iyz="-1.21858577871576E-06" izz="1.21905238907251E-06"/>
      </inertial>
      <visual>
        <origin rpy="0 0 0" xyz="0 0 0"/>
        <geometry>
          <mesh filename="package://robotiq_140_gripper_description/meshes/robotiq_140_right_outer_knuckle.dae"/>
        </geometry>
        <material name="">
          <color rgba="0.792156862745098 0.819607843137255 0.933333333333333 1"/>
        </material>
      </visual>
      <collision>
        <origin rpy="0 0 0" xyz="0 0 0"/>
        <geometry>
          <mesh filename="package://robotiq_140_gripper_description/meshes/robotiq_140_right_outer_knuckle.dae"/>
        </geometry>
      </collision>
    </link>
    <gazebo reference="right_outer_knuckle">
      <material>Gazebo/Grey</material>
      <selfCollide>False</selfCollide>
    </gazebo>
    <link name="left_inner_knuckle">
      <inertial>
        <origin rpy="0 0 0" xyz="0.000123011831763771 0.0507850843201817 0.00103968640075166"/>
	<mass value="0.002"/> <!--0.0271177346495152"-->
        <inertia ixx="2.61910379223783E-05" ixy="-2.43616858946494E-07" ixz="-6.37789906117123E-09" iyy="2.8270243746167E-06" iyz="-5.37200748039765E-07" izz="2.83695868220296E-05"/>
      </inertial>
      <visual>
        <origin rpy="0 0 0" xyz="0 0 0"/>
        <geometry>
          <mesh filename="package://robotiq_140_gripper_description/meshes/robotiq_140_left_inner_knuckle.dae"/>
        </geometry>
        <material name="Gazebo/Black">
          <color rgba="0.1 0.1 0.1 1"/>
        </material>
      </visual>
    </link>
    <gazebo reference="left_inner_knuckle">
      <material>Gazebo/Black</material>
      <selfCollide>False</selfCollide>
    </gazebo>
    <link name="right_inner_knuckle">
      <inertial>
        <origin rpy="0 0 0" xyz="0.000123011831763771 0.0507850843201817 0.00103968640075166"/>
	<mass value="0.002"/> <!--0.0271177346495152"-->
        <inertia ixx="2.61910379223783E-05" ixy="-2.43616858946494E-07" ixz="-6.37789906117123E-09" iyy="2.8270243746167E-06" iyz="-5.37200748039765E-07" izz="2.83695868220296E-05"/>
      </inertial>
      <visual>
        <origin rpy="0 0 0" xyz="0 0 0"/>
        <geometry>
          <mesh filename="package://robotiq_140_gripper_description/meshes/robotiq_140_right_inner_knuckle.dae"/>
        </geometry>
        <material name="Gazebo/Black">
          <color rgba="0.1 0.1 0.1 1"/>
        </material>
      </visual>
    </link>
    <gazebo reference="right_inner_knuckle">
      <material>Gazebo/Black</material>
      <selfCollide>False</selfCollide>
    </gazebo>
    <link name="left_inner_finger">
      <inertial>
        <origin rpy="0 0 0" xyz="0.0 0.031506174 -0.017648840"/>
	<mass value="0.002"/> <!--0.0104003125914103"-->
        <inertia ixx="2.71909453810972E-06" ixy="1.35402465472579E-21" ixz="-7.1817349065269E-22" iyy="7.69100314106116E-07" iyz="6.74715432769696E-07" izz="2.30315190420171E-06"/>
      </inertial>
      <visual>
        <origin rpy="0 0 0" xyz="0 0 0"/>
        <geometry>
          <mesh filename="package://robotiq_140_gripper_description/meshes/robotiq_140_left_inner_finger.dae" scale="0.001 0.001 0.001"/>
        </geometry>
        <material name="Gazebo/Black">
          <color rgba="0.1 0.1 0.1 1"/>
        </material>
      </visual>
      <collision>
        <origin rpy="0 0 0" xyz="0 0 0"/>
        <geometry>
          <mesh filename="package://robotiq_140_gripper_description/meshes/robotiq_140_left_inner_finger.dae" scale="0.001 0.001 0.001"/>
        </geometry>
      </collision>
    </link>
    <gazebo reference="left_inner_finger">
      <material>Gazebo/Black</material>
      <selfCollide>False</selfCollide>
      <surface>
          <friction>
            <ode>
              <mu>100000</mu>
              <mu2>100000</mu2>
            </ode>
          </friction>
      </surface>
    </gazebo>
    <link name="right_inner_finger">
      <inertial>
        <origin rpy="0 0 0" xyz="0.0 0.031506174 -0.017648840"/>
	<mass value="0.002"/> <!--0.0104003125914103"-->
        <inertia ixx="2.71909453810972E-06" ixy="1.35402465472579E-21" ixz="-7.1817349065269E-22" iyy="7.69100314106116E-07" iyz="6.74715432769696E-07" izz="2.30315190420171E-06"/>
      </inertial>
      <visual>
        <origin rpy="0 0 0" xyz="0 0 0"/>
        <geometry>
          <mesh filename="package://robotiq_140_gripper_description/meshes/robotiq_140_right_inner_finger.dae" scale="0.001 0.001 0.001"/>
        </geometry>
        <material name="Gazebo/Black">
          <color rgba="0.1 0.1 0.1 1"/>
        </material>
      </visual>
      <collision>
        <origin rpy="0 0 0" xyz="0 0 0"/>
        <geometry>
          <mesh filename="package://robotiq_140_gripper_description/meshes/robotiq_140_right_inner_finger.dae" scale="0.001 0.001 0.001"/>
        </geometry>
      </collision>
    </link>
    <gazebo reference="right_inner_finger">
      <material>Gazebo/Black</material>
      <selfCollide>False</selfCollide>
      <surface>
          <friction>
            <ode>
              <mu>100000</mu>
              <mu2>100000</mu2>
            </ode>
          </friction>
      </surface>
    </gazebo>
    <link name="left_outer_finger">
      <inertial>
        <origin rpy="0 0 0" xyz="0.00030115855001899 0.0373907951953854 -0.0208027427000385"/>
	<mass value="0.002"/> <!--0.022614240507152"-->
        <inertia ixx="1.52518312458174E-05" ixy="9.76583423954399E-10" ixz="-5.43838577022588E-10" iyy="6.17694243867776E-06" iyz="6.78636130740228E-06" izz="1.16494917907219E-05"/>
      </inertial>
      <visual>
        <origin rpy="0 0 0" xyz="0 0 0"/>
        <geometry>
          <mesh filename="package://robotiq_140_gripper_description/meshes/robotiq_140_left_outer_finger.dae"/>
        </geometry>
        <material name="Gazebo/Black">
          <color rgba="0.1 0.1 0.1 1"/>
        </material>
      </visual>
      <collision>
        <origin rpy="0 0 0" xyz="0 0 0"/>
        <geometry>
          <mesh filename="package://robotiq_140_gripper_description/meshes/robotiq_140_left_outer_finger.dae"/>
        </geometry>
      </collision>
    </link>
    <gazebo reference="left_outer_finger">
      <material>Gazebo/Black</material>
      <selfCollide>False</selfCollide>
    </gazebo>
    <link name="right_outer_finger">
      <inertial>
        <origin rpy="0 0 0" xyz="0.00030115855001899 0.0373907951953854 -0.0208027427000385"/>
	<mass value="0.002"/> <!--0.022614240507152"-->
        <inertia ixx="1.52518312458174E-05" ixy="9.76583423954399E-10" ixz="-5.43838577022588E-10" iyy="6.17694243867776E-06" iyz="6.78636130740228E-06" izz="1.16494917907219E-05"/>
      </inertial>
      <visual>
        <origin rpy="0 0 0" xyz="0 0 0"/>
        <geometry>
          <mesh filename="package://robotiq_140_gripper_description/meshes/robotiq_140_right_outer_finger.dae"/>
        </geometry>
        <material name="Gazebo/Black">
          <color rgba="0.1 0.1 0.1 1"/>
        </material>
      </visual>
      <collision>
        <origin rpy="0 0 0" xyz="0 0 0"/>
        <geometry>
          <mesh filename="package://robotiq_140_gripper_description/meshes/robotiq_140_right_outer_finger.dae"/>
        </geometry>
      </collision>
    </link>
    <gazebo reference="right_outer_finger">
      <material>Gazebo/Black</material>
      <selfCollide>False</selfCollide>
    </gazebo>
    <joint name="left_outer_knuckle_joint" type="revolute">
      <origin rpy="2.31 0 0" xyz="0 -0.030601 0.054905"/>
      <parent link="robotiq_arg2f_base_link"/>
      <child link="left_outer_knuckle"/>
      <axis xyz="-1 0 0"/>
      <limit effort="1000" lower="0" upper="0.775" velocity="2.0"/>
      <mimic joint="joint_finger" multiplier="1" offset="0"/>
    </joint>
    <joint name="joint_finger" type="revolute">
      <origin rpy="2.31 0 3.14159265359" xyz="0 0.030601 0.054905"/>
      <parent link="robotiq_arg2f_base_link"/>
      <child link="right_outer_knuckle"/>
      <axis xyz="-1 0 0"/>
      <limit effort="1000" lower="0" upper="0.775" velocity="2.0"/>
    </joint>
    <joint name="left_inner_knuckle_joint" type="revolute">
      <origin rpy="2.29 0 0" xyz="0 -0.0127 0.06142"/>
      <parent link="robotiq_arg2f_base_link"/>
      <child link="left_inner_knuckle"/>
      <axis xyz="-1 0 0"/>
      <limit effort="1000" lower="0" upper="0.78" velocity="2.0"/>
      <mimic joint="joint_finger" multiplier="1" offset="0"/>
    </joint>
    <joint name="right_inner_knuckle_joint" type="revolute">
      <origin rpy="2.29 0 -3.14159265359" xyz="0 0.0127 0.06142"/>
      <parent link="robotiq_arg2f_base_link"/>
      <child link="right_inner_knuckle"/>
      <axis xyz="-1 0 0"/>
      <limit effort="1000" lower="0" upper="0.78" velocity="2.0"/>
      <mimic joint="joint_finger" multiplier="1" offset="0"/>
    </joint>
    <joint name="left_outer_finger_joint" type="fixed">
      <origin rpy="0 0 0" xyz="0 0.01821998610742 0.0260018192872234"/>
      <parent link="left_outer_knuckle"/>
      <child link="left_outer_finger"/>
    </joint>
    <joint name="right_outer_finger_joint" type="fixed">
      <origin rpy="0 0 0" xyz="0 0.01821998610742 0.0260018192872234"/>
      <parent link="right_outer_knuckle"/>
      <child link="right_outer_finger"/>
    </joint>
    <joint name="left_inner_finger_joint" type="revolute">
      <origin rpy="-.725 0 0" xyz="0 0.0817554015893473 -0.0282203446692936"/>
      <parent link="left_outer_finger"/>
      <child link="left_inner_finger"/>
      <axis xyz="1 0 0"/>
      <limit effort="1000" lower="0" upper="0.8757" velocity="2.0"/>
      <mimic joint="joint_finger" multiplier="1" offset="0"/>
    </joint>
    <joint name="right_inner_finger_joint" type="revolute">
      <origin rpy="-.725 0 0" xyz="0 0.0817554015893473 -0.0282203446692936"/>
      <parent link="right_outer_finger"/>
      <child link="right_inner_finger"/>
      <axis xyz="1 0 0"/>
      <limit effort="1000" lower="0" upper="0.8757" velocity="2.0"/>
      <mimic joint="joint_finger" multiplier="1" offset="0"/>
    </joint>
    <gazebo>
      <joint name="left_inner_finger_knuckle_joint" type="revolute">
        <pose frame="">0 0.006 -0.018 0 0 0</pose>
        <parent>mara::left_inner_knuckle</parent>
        <child>mara::left_inner_finger</child>
        <axis>
          <xyz>1 0 0</xyz>
          <limit>
            <lower>-0.8</lower>
            <upper>0.8</upper>
            <velocity>2.0</velocity>
            <effort>1000</effort>
          </limit>
        </axis>
      </joint>
      <joint name="right_inner_finger_knuckle_joint" type="revolute">
        <pose frame="">0 0.006 -0.018 0 0 0</pose>
        <parent>mara::right_inner_knuckle</parent>
        <child>mara::right_inner_finger</child>
        <axis>
          <xyz>-1 0 0</xyz>
          <limit>
            <lower>-0.8</lower>
            <upper>0.8</upper>
            <velocity>2.0</velocity>
            <effort>1000</effort>
          </limit>
        </axis>
      </joint>
      <plugin filename="librobotiq_gripper_gazebo_plugin.so" name="hrim_actuation_gripper_000000000004">
        <joint>left_inner_knuckle_joint</joint>
        <joint>left_outer_knuckle_joint</joint>
        <joint>right_inner_knuckle_joint</joint>
        <joint>joint_finger</joint>
      </plugin>
      <plugin filename="libgazebo_ros_joint_state_publisher.so" name="mara_joint_state">
        <ros>
          <argument>~/out:=joint_states</argument>
        </ros>
        <update_rate>25</update_rate>
        <joint_name>joint_finger</joint_name>
      </plugin>
    </gazebo>

<!--
  <gazebo>
    <plugin filename="libgazebo_ros_f3d.so" name="gazebo_ros_f3d">
      <alwaysOn>true</alwaysOn>
      <updateRate>100.0</updateRate>
      <bodyName>delta/base_link</bodyName>
      <topicName>base_link/f3d</topicName>
      <frameName>delta/base_link</frameName>
    </plugin>
  </gazebo>
-->

  <gazebo>
    <plugin filename="libmara_gazebo_joint_training_plugin_3dof.so" name="hrim_actuation_servomotor_00000000000">
      <ros/>
      <axis1>motor2</axis1>
      <axis2>motor1</axis2>
      <axis3>motor3</axis3>
    </plugin>
  </gazebo>
<!--
  <gazebo>
    <plugin filename="libgazebo_ros_joint_state_publisher.so" name="mara_joint_state">
      <ros>
        <argument>~/out:=joint_states</argument>
      </ros>
      <update_rate>25</update_rate>
    </plugin>
  </gazebo>
-->
</robot>
